43:46: execution error: Google Chrome got an error: Can’t get window 1. Invalid index. (-1719)
43:48: execution error: Google Chrome got an error: Can’t get window 1. Invalid index. (-1719)
50:131: execution error: Google Chrome got an error: Can’t get window 1. Invalid index. (-1719)
43:48: execution error: Google Chrome got an error: Connection is invalid. (-609)
50:131: execution error: Google Chrome got an error: Can’t get window 1. Invalid index. (-1719)
50:131: execution error: Google Chrome got an error: AppleEvent timed out. (-1712)
43:46: execution error: Google Chrome got an error: Can’t get window 1. Invalid index. (-1719)
43:48: execution error: Google Chrome got an error: Can’t get window 1. Invalid index. (-1719)
50:131: execution error: Google Chrome got an error: Can’t get window 1. Invalid index. (-1719)
Traceback (most recent call last):
  File "/Users/r/.virtualenvs/focus-tracker/lib/python3.7/site-packages/google/api_core/grpc_helpers.py", line 57, in error_remapped_callable
    return callable_(*args, **kwargs)
  File "/Users/r/.virtualenvs/focus-tracker/lib/python3.7/site-packages/grpc/_channel.py", line 923, in __call__
    return _end_unary_response_blocking(state, call, False, None)
  File "/Users/r/.virtualenvs/focus-tracker/lib/python3.7/site-packages/grpc/_channel.py", line 826, in _end_unary_response_blocking
    raise _InactiveRpcError(state)
grpc._channel._InactiveRpcError: <_InactiveRpcError of RPC that terminated with:
	status = StatusCode.INVALID_ARGUMENT
	details = "The language no is not supported for classify_text analysis."
	debug_error_string = "{"created":"@1609611745.332710000","description":"Error received from peer ipv4:142.250.64.170:443","file":"src/core/lib/surface/call.cc","file_line":1063,"grpc_message":"The language no is not supported for classify_text analysis.","grpc_status":3}"
>

The above exception was the direct cause of the following exception:

Traceback (most recent call last):
  File "/Users/r/PycharmProjects/focus-tracker/getdata.py", line 44, in <module>
    managedata.tabulate()
  File "/Users/r/PycharmProjects/focus-tracker/managedata.py", line 33, in tabulate
    listToPut["classification"] = (classificationexample.classify(htstr))
  File "/Users/r/PycharmProjects/focus-tracker/classificationexample.py", line 22, in classify
    response = language_client.classify_text(request={'document': document})
  File "/Users/r/.virtualenvs/focus-tracker/lib/python3.7/site-packages/google/cloud/language_v1/services/language_service/client.py", line 614, in classify_text
    response = rpc(request, retry=retry, timeout=timeout, metadata=metadata,)
  File "/Users/r/.virtualenvs/focus-tracker/lib/python3.7/site-packages/google/api_core/gapic_v1/method.py", line 145, in __call__
    return wrapped_func(*args, **kwargs)
  File "/Users/r/.virtualenvs/focus-tracker/lib/python3.7/site-packages/google/api_core/retry.py", line 286, in retry_wrapped_func
    on_error=on_error,
  File "/Users/r/.virtualenvs/focus-tracker/lib/python3.7/site-packages/google/api_core/retry.py", line 184, in retry_target
    return target()
  File "/Users/r/.virtualenvs/focus-tracker/lib/python3.7/site-packages/google/api_core/grpc_helpers.py", line 59, in error_remapped_callable
    six.raise_from(exceptions.from_grpc_error(exc), exc)
  File "<string>", line 3, in raise_from
google.api_core.exceptions.InvalidArgument: 400 The language no is not supported for classify_text analysis.
Traceback (most recent call last):
  File "/Users/r/PycharmProjects/focus-tracker/getdata.py", line 7, in <module>
    import managedata
  File "/Users/r/PycharmProjects/focus-tracker/managedata.py", line 10, in <module>
    import classificationexample
  File "/Users/r/PycharmProjects/focus-tracker/classificationexample.py", line 115
    sample_analyze_sentiment("dislike")
    ^
IndentationError: expected an indented block
Traceback (most recent call last):
  File "/Users/r/PycharmProjects/focus-tracker/getdata.py", line 7, in <module>
    import managedata
  File "/Users/r/PycharmProjects/focus-tracker/managedata.py", line 10, in <module>
    import classificationexample
  File "/Users/r/PycharmProjects/focus-tracker/classificationexample.py", line 115
    sample_analyze_sentiment("dislike")
    ^
IndentationError: expected an indented block
Traceback (most recent call last):
  File "/Users/r/PycharmProjects/focus-tracker/getdata.py", line 7, in <module>
    import managedata
  File "/Users/r/PycharmProjects/focus-tracker/managedata.py", line 10, in <module>
    import classificationexample
  File "/Users/r/PycharmProjects/focus-tracker/classificationexample.py", line 115
    sample_analyze_sentiment("dislike")
    ^
IndentationError: expected an indented block
Traceback (most recent call last):
  File "/Users/r/PycharmProjects/focus-tracker/getdata.py", line 82, in <module>
    endsupresstime = time.time()+int(inp)*60
ValueError: invalid literal for int() with base 10: '0.1'
Traceback (most recent call last):
  File "/Users/r/.virtualenvs/focus-tracker/lib/python3.7/site-packages/google/api_core/grpc_helpers.py", line 57, in error_remapped_callable
    return callable_(*args, **kwargs)
  File "/Users/r/.virtualenvs/focus-tracker/lib/python3.7/site-packages/grpc/_channel.py", line 923, in __call__
    return _end_unary_response_blocking(state, call, False, None)
  File "/Users/r/.virtualenvs/focus-tracker/lib/python3.7/site-packages/grpc/_channel.py", line 826, in _end_unary_response_blocking
    raise _InactiveRpcError(state)
grpc._channel._InactiveRpcError: <_InactiveRpcError of RPC that terminated with:
	status = StatusCode.UNAVAILABLE
	details = "failed to connect to all addresses"
	debug_error_string = "{"created":"@1609789385.701331000","description":"Failed to pick subchannel","file":"src/core/ext/filters/client_channel/client_channel.cc","file_line":4143,"referenced_errors":[{"created":"@1609789385.701329000","description":"failed to connect to all addresses","file":"src/core/ext/filters/client_channel/lb_policy/pick_first/pick_first.cc","file_line":398,"grpc_status":14}]}"
>

The above exception was the direct cause of the following exception:

Traceback (most recent call last):
  File "/Users/r/.virtualenvs/focus-tracker/lib/python3.7/site-packages/google/api_core/retry.py", line 184, in retry_target
    return target()
  File "/Users/r/.virtualenvs/focus-tracker/lib/python3.7/site-packages/google/api_core/grpc_helpers.py", line 59, in error_remapped_callable
    six.raise_from(exceptions.from_grpc_error(exc), exc)
  File "<string>", line 3, in raise_from
google.api_core.exceptions.ServiceUnavailable: 503 failed to connect to all addresses

The above exception was the direct cause of the following exception:

Traceback (most recent call last):
  File "/Users/r/PycharmProjects/focus-tracker/getdata.py", line 59, in <module>
    managedata.tabulate()
  File "/Users/r/PycharmProjects/focus-tracker/managedata.py", line 33, in tabulate
    listToPut["classification"] = (classificationexample.classify(htstr))
  File "/Users/r/PycharmProjects/focus-tracker/classificationexample.py", line 22, in classify
    response = language_client.classify_text(request={'document': document})
  File "/Users/r/.virtualenvs/focus-tracker/lib/python3.7/site-packages/google/cloud/language_v1/services/language_service/client.py", line 614, in classify_text
    response = rpc(request, retry=retry, timeout=timeout, metadata=metadata,)
  File "/Users/r/.virtualenvs/focus-tracker/lib/python3.7/site-packages/google/api_core/gapic_v1/method.py", line 145, in __call__
    return wrapped_func(*args, **kwargs)
  File "/Users/r/.virtualenvs/focus-tracker/lib/python3.7/site-packages/google/api_core/retry.py", line 286, in retry_wrapped_func
    on_error=on_error,
  File "/Users/r/.virtualenvs/focus-tracker/lib/python3.7/site-packages/google/api_core/retry.py", line 206, in retry_target
    last_exc,
  File "<string>", line 3, in raise_from
google.api_core.exceptions.RetryError: Deadline of 120.0s exceeded while calling functools.partial(<function _wrap_unary_errors.<locals>.error_remapped_callable at 0x1089e8560>, document {
  type_: PLAIN_TEXT
  content: "![](current/images/usaco_logo.png)\n\n  * Overview\n  * Training\n  * Contests\n  * History\n  * Staff\n  * Resources\n\n  \n\n##  USACO 2019 US Open Contest, Platinum\n\n##  Problem 1. Tree Boxes\n\nReturn to Problem List  \nContest has ended.\n\n  \n\n![](current/images/medal_none.png)\n\n**Log in to allow submissions in analysis mode**\n\n  \n\nEnglish (en) French (fr) Russian (ru) Spanish (es) Chinese (zh)\n\nFarmer John is planning to build NN (1 N 1051 N 105) farms that will be\nconnected by N 1N 1 roads, forming a tree. Typically, whenever one of his\nfarms is having an issue he is not told the specific farm that is having an\nissue. Instead, he is told that one of the farms along the path from some farm\nAA to another farm BB is having an issue. This is often confusing for Farmer\nJohn, as he usually drives offroad tractors and isn\'t familiar with the road\nsystem.\n\nFarmer John considers the location of a farm to be a 2D point. He would prefer\nto be told that there is a problem in one of the farms in a specifie"
}
, metadata=[('x-goog-api-client', 'gl-python/3.7.4 grpc/1.34.0 gax/1.24.1 gapic/2.0.0')]), last exception: 503 failed to connect to all addresses
Traceback (most recent call last):
  File "/Users/r/.virtualenvs/focus-tracker/lib/python3.7/site-packages/google/api_core/grpc_helpers.py", line 57, in error_remapped_callable
    return callable_(*args, **kwargs)
  File "/Users/r/.virtualenvs/focus-tracker/lib/python3.7/site-packages/grpc/_channel.py", line 923, in __call__
    return _end_unary_response_blocking(state, call, False, None)
  File "/Users/r/.virtualenvs/focus-tracker/lib/python3.7/site-packages/grpc/_channel.py", line 826, in _end_unary_response_blocking
    raise _InactiveRpcError(state)
grpc._channel._InactiveRpcError: <_InactiveRpcError of RPC that terminated with:
	status = StatusCode.UNAVAILABLE
	details = "failed to connect to all addresses"
	debug_error_string = "{"created":"@1609789532.336814000","description":"Failed to pick subchannel","file":"src/core/ext/filters/client_channel/client_channel.cc","file_line":4143,"referenced_errors":[{"created":"@1609789532.336812000","description":"failed to connect to all addresses","file":"src/core/ext/filters/client_channel/lb_policy/pick_first/pick_first.cc","file_line":398,"grpc_status":14}]}"
>

The above exception was the direct cause of the following exception:

Traceback (most recent call last):
  File "/Users/r/.virtualenvs/focus-tracker/lib/python3.7/site-packages/google/api_core/retry.py", line 184, in retry_target
    return target()
  File "/Users/r/.virtualenvs/focus-tracker/lib/python3.7/site-packages/google/api_core/grpc_helpers.py", line 59, in error_remapped_callable
    six.raise_from(exceptions.from_grpc_error(exc), exc)
  File "<string>", line 3, in raise_from
google.api_core.exceptions.ServiceUnavailable: 503 failed to connect to all addresses

The above exception was the direct cause of the following exception:

Traceback (most recent call last):
  File "/Users/r/PycharmProjects/focus-tracker/getdata.py", line 59, in <module>
    managedata.tabulate()
  File "/Users/r/PycharmProjects/focus-tracker/managedata.py", line 33, in tabulate
    listToPut["classification"] = (classificationexample.classify(htstr))
  File "/Users/r/PycharmProjects/focus-tracker/classificationexample.py", line 22, in classify
    response = language_client.classify_text(request={'document': document})
  File "/Users/r/.virtualenvs/focus-tracker/lib/python3.7/site-packages/google/cloud/language_v1/services/language_service/client.py", line 614, in classify_text
    response = rpc(request, retry=retry, timeout=timeout, metadata=metadata,)
  File "/Users/r/.virtualenvs/focus-tracker/lib/python3.7/site-packages/google/api_core/gapic_v1/method.py", line 145, in __call__
    return wrapped_func(*args, **kwargs)
  File "/Users/r/.virtualenvs/focus-tracker/lib/python3.7/site-packages/google/api_core/retry.py", line 286, in retry_wrapped_func
    on_error=on_error,
  File "/Users/r/.virtualenvs/focus-tracker/lib/python3.7/site-packages/google/api_core/retry.py", line 206, in retry_target
    last_exc,
  File "<string>", line 3, in raise_from
google.api_core.exceptions.RetryError: Deadline of 120.0s exceeded while calling functools.partial(<function _wrap_unary_errors.<locals>.error_remapped_callable at 0x108796d40>, document {
  type_: PLAIN_TEXT
  content: "![](current/images/usaco_logo.png)\n\n  * Overview\n  * Training\n  * Contests\n  * History\n  * Staff\n  * Resources\n\n  \n\n##  USACO 2019 US Open Contest, Platinum\n\n##  Problem 1. Tree Boxes\n\nReturn to Problem List  \nContest has ended.\n\n  \n\n![](current/images/medal_none.png)\n\n**Log in to allow submissions in analysis mode**\n\n  \n\nEnglish (en) French (fr) Russian (ru) Spanish (es) Chinese (zh)\n\nFarmer John is planning to build NN (1 N 1051 N 105) farms that will be\nconnected by N 1N 1 roads, forming a tree. Typically, whenever one of his\nfarms is having an issue he is not told the specific farm that is having an\nissue. Instead, he is told that one of the farms along the path from some farm\nAA to another farm BB is having an issue. This is often confusing for Farmer\nJohn, as he usually drives offroad tractors and isn\'t familiar with the road\nsystem.\n\nFarmer John considers the location of a farm to be a 2D point. He would prefer\nto be told that there is a problem in one of the farms in a specifie"
}
, metadata=[('x-goog-api-client', 'gl-python/3.7.4 grpc/1.34.0 gax/1.24.1 gapic/2.0.0')]), last exception: 503 failed to connect to all addresses
Traceback (most recent call last):
  File "/Users/r/.virtualenvs/focus-tracker/lib/python3.7/site-packages/google/api_core/grpc_helpers.py", line 57, in error_remapped_callable
    return callable_(*args, **kwargs)
  File "/Users/r/.virtualenvs/focus-tracker/lib/python3.7/site-packages/grpc/_channel.py", line 923, in __call__
    return _end_unary_response_blocking(state, call, False, None)
  File "/Users/r/.virtualenvs/focus-tracker/lib/python3.7/site-packages/grpc/_channel.py", line 826, in _end_unary_response_blocking
    raise _InactiveRpcError(state)
grpc._channel._InactiveRpcError: <_InactiveRpcError of RPC that terminated with:
	status = StatusCode.UNAVAILABLE
	details = "failed to connect to all addresses"
	debug_error_string = "{"created":"@1609789675.280318000","description":"Failed to pick subchannel","file":"src/core/ext/filters/client_channel/client_channel.cc","file_line":4143,"referenced_errors":[{"created":"@1609789675.280316000","description":"failed to connect to all addresses","file":"src/core/ext/filters/client_channel/lb_policy/pick_first/pick_first.cc","file_line":398,"grpc_status":14}]}"
>

The above exception was the direct cause of the following exception:

Traceback (most recent call last):
  File "/Users/r/.virtualenvs/focus-tracker/lib/python3.7/site-packages/google/api_core/retry.py", line 184, in retry_target
    return target()
  File "/Users/r/.virtualenvs/focus-tracker/lib/python3.7/site-packages/google/api_core/grpc_helpers.py", line 59, in error_remapped_callable
    six.raise_from(exceptions.from_grpc_error(exc), exc)
  File "<string>", line 3, in raise_from
google.api_core.exceptions.ServiceUnavailable: 503 failed to connect to all addresses

The above exception was the direct cause of the following exception:

Traceback (most recent call last):
  File "/Users/r/PycharmProjects/focus-tracker/getdata.py", line 59, in <module>
    managedata.tabulate()
  File "/Users/r/PycharmProjects/focus-tracker/managedata.py", line 33, in tabulate
    listToPut["classification"] = (classificationexample.classify(htstr))
  File "/Users/r/PycharmProjects/focus-tracker/classificationexample.py", line 22, in classify
    response = language_client.classify_text(request={'document': document})
  File "/Users/r/.virtualenvs/focus-tracker/lib/python3.7/site-packages/google/cloud/language_v1/services/language_service/client.py", line 614, in classify_text
    response = rpc(request, retry=retry, timeout=timeout, metadata=metadata,)
  File "/Users/r/.virtualenvs/focus-tracker/lib/python3.7/site-packages/google/api_core/gapic_v1/method.py", line 145, in __call__
    return wrapped_func(*args, **kwargs)
  File "/Users/r/.virtualenvs/focus-tracker/lib/python3.7/site-packages/google/api_core/retry.py", line 286, in retry_wrapped_func
    on_error=on_error,
  File "/Users/r/.virtualenvs/focus-tracker/lib/python3.7/site-packages/google/api_core/retry.py", line 206, in retry_target
    last_exc,
  File "<string>", line 3, in raise_from
google.api_core.exceptions.RetryError: Deadline of 120.0s exceeded while calling functools.partial(<function _wrap_unary_errors.<locals>.error_remapped_callable at 0x105cf2d40>, document {
  type_: PLAIN_TEXT
  content: "![](current/images/usaco_logo.png)\n\n  * Overview\n  * Training\n  * Contests\n  * History\n  * Staff\n  * Resources\n\n  \n\n##  USACO 2019 US Open Contest, Platinum\n\n##  Problem 1. Tree Boxes\n\nReturn to Problem List  \nContest has ended.\n\n  \n\n![](current/images/medal_none.png)\n\n**Log in to allow submissions in analysis mode**\n\n  \n\nEnglish (en) French (fr) Russian (ru) Spanish (es) Chinese (zh)\n\nFarmer John is planning to build NN (1 N 1051 N 105) farms that will be\nconnected by N 1N 1 roads, forming a tree. Typically, whenever one of his\nfarms is having an issue he is not told the specific farm that is having an\nissue. Instead, he is told that one of the farms along the path from some farm\nAA to another farm BB is having an issue. This is often confusing for Farmer\nJohn, as he usually drives offroad tractors and isn\'t familiar with the road\nsystem.\n\nFarmer John considers the location of a farm to be a 2D point. He would prefer\nto be told that there is a problem in one of the farms in a specifie"
}
, metadata=[('x-goog-api-client', 'gl-python/3.7.4 grpc/1.34.0 gax/1.24.1 gapic/2.0.0')]), last exception: 503 failed to connect to all addresses
Traceback (most recent call last):
  File "/Users/r/.virtualenvs/focus-tracker/lib/python3.7/site-packages/google/api_core/grpc_helpers.py", line 57, in error_remapped_callable
    return callable_(*args, **kwargs)
  File "/Users/r/.virtualenvs/focus-tracker/lib/python3.7/site-packages/grpc/_channel.py", line 923, in __call__
    return _end_unary_response_blocking(state, call, False, None)
  File "/Users/r/.virtualenvs/focus-tracker/lib/python3.7/site-packages/grpc/_channel.py", line 826, in _end_unary_response_blocking
    raise _InactiveRpcError(state)
grpc._channel._InactiveRpcError: <_InactiveRpcError of RPC that terminated with:
	status = StatusCode.UNAVAILABLE
	details = "failed to connect to all addresses"
	debug_error_string = "{"created":"@1609789798.093169000","description":"Failed to pick subchannel","file":"src/core/ext/filters/client_channel/client_channel.cc","file_line":4143,"referenced_errors":[{"created":"@1609789798.093167000","description":"failed to connect to all addresses","file":"src/core/ext/filters/client_channel/lb_policy/pick_first/pick_first.cc","file_line":398,"grpc_status":14}]}"
>

The above exception was the direct cause of the following exception:

Traceback (most recent call last):
  File "/Users/r/.virtualenvs/focus-tracker/lib/python3.7/site-packages/google/api_core/retry.py", line 184, in retry_target
    return target()
  File "/Users/r/.virtualenvs/focus-tracker/lib/python3.7/site-packages/google/api_core/grpc_helpers.py", line 59, in error_remapped_callable
    six.raise_from(exceptions.from_grpc_error(exc), exc)
  File "<string>", line 3, in raise_from
google.api_core.exceptions.ServiceUnavailable: 503 failed to connect to all addresses

The above exception was the direct cause of the following exception:

Traceback (most recent call last):
  File "/Users/r/PycharmProjects/focus-tracker/getdata.py", line 59, in <module>
    managedata.tabulate()
  File "/Users/r/PycharmProjects/focus-tracker/managedata.py", line 33, in tabulate
    listToPut["classification"] = (classificationexample.classify(htstr))
  File "/Users/r/PycharmProjects/focus-tracker/classificationexample.py", line 22, in classify
    response = language_client.classify_text(request={'document': document})
  File "/Users/r/.virtualenvs/focus-tracker/lib/python3.7/site-packages/google/cloud/language_v1/services/language_service/client.py", line 614, in classify_text
    response = rpc(request, retry=retry, timeout=timeout, metadata=metadata,)
  File "/Users/r/.virtualenvs/focus-tracker/lib/python3.7/site-packages/google/api_core/gapic_v1/method.py", line 145, in __call__
    return wrapped_func(*args, **kwargs)
  File "/Users/r/.virtualenvs/focus-tracker/lib/python3.7/site-packages/google/api_core/retry.py", line 286, in retry_wrapped_func
    on_error=on_error,
  File "/Users/r/.virtualenvs/focus-tracker/lib/python3.7/site-packages/google/api_core/retry.py", line 206, in retry_target
    last_exc,
  File "<string>", line 3, in raise_from
google.api_core.exceptions.RetryError: Deadline of 120.0s exceeded while calling functools.partial(<function _wrap_unary_errors.<locals>.error_remapped_callable at 0x1057dfd40>, document {
  type_: PLAIN_TEXT
  content: "![](current/images/usaco_logo.png)\n\n  * Overview\n  * Training\n  * Contests\n  * History\n  * Staff\n  * Resources\n\n  \n\n##  USACO 2019 US Open Contest, Platinum\n\n##  Problem 1. Tree Boxes\n\nReturn to Problem List  \nContest has ended.\n\n  \n\n![](current/images/medal_none.png)\n\n**Log in to allow submissions in analysis mode**\n\n  \n\nEnglish (en) French (fr) Russian (ru) Spanish (es) Chinese (zh)\n\nFarmer John is planning to build NN (1 N 1051 N 105) farms that will be\nconnected by N 1N 1 roads, forming a tree. Typically, whenever one of his\nfarms is having an issue he is not told the specific farm that is having an\nissue. Instead, he is told that one of the farms along the path from some farm\nAA to another farm BB is having an issue. This is often confusing for Farmer\nJohn, as he usually drives offroad tractors and isn\'t familiar with the road\nsystem.\n\nFarmer John considers the location of a farm to be a 2D point. He would prefer\nto be told that there is a problem in one of the farms in a specifie"
}
, metadata=[('x-goog-api-client', 'gl-python/3.7.4 grpc/1.34.0 gax/1.24.1 gapic/2.0.0')]), last exception: 503 failed to connect to all addresses
Traceback (most recent call last):
  File "/Users/r/.virtualenvs/focus-tracker/lib/python3.7/site-packages/google/api_core/grpc_helpers.py", line 57, in error_remapped_callable
    return callable_(*args, **kwargs)
  File "/Users/r/.virtualenvs/focus-tracker/lib/python3.7/site-packages/grpc/_channel.py", line 923, in __call__
    return _end_unary_response_blocking(state, call, False, None)
  File "/Users/r/.virtualenvs/focus-tracker/lib/python3.7/site-packages/grpc/_channel.py", line 826, in _end_unary_response_blocking
    raise _InactiveRpcError(state)
grpc._channel._InactiveRpcError: <_InactiveRpcError of RPC that terminated with:
	status = StatusCode.UNAVAILABLE
	details = "failed to connect to all addresses"
	debug_error_string = "{"created":"@1609789941.626778000","description":"Failed to pick subchannel","file":"src/core/ext/filters/client_channel/client_channel.cc","file_line":4143,"referenced_errors":[{"created":"@1609789941.626776000","description":"failed to connect to all addresses","file":"src/core/ext/filters/client_channel/lb_policy/pick_first/pick_first.cc","file_line":398,"grpc_status":14}]}"
>

The above exception was the direct cause of the following exception:

Traceback (most recent call last):
  File "/Users/r/.virtualenvs/focus-tracker/lib/python3.7/site-packages/google/api_core/retry.py", line 184, in retry_target
    return target()
  File "/Users/r/.virtualenvs/focus-tracker/lib/python3.7/site-packages/google/api_core/grpc_helpers.py", line 59, in error_remapped_callable
    six.raise_from(exceptions.from_grpc_error(exc), exc)
  File "<string>", line 3, in raise_from
google.api_core.exceptions.ServiceUnavailable: 503 failed to connect to all addresses

The above exception was the direct cause of the following exception:

Traceback (most recent call last):
  File "/Users/r/PycharmProjects/focus-tracker/getdata.py", line 59, in <module>
    managedata.tabulate()
  File "/Users/r/PycharmProjects/focus-tracker/managedata.py", line 33, in tabulate
    listToPut["classification"] = (classificationexample.classify(htstr))
  File "/Users/r/PycharmProjects/focus-tracker/classificationexample.py", line 22, in classify
    response = language_client.classify_text(request={'document': document})
  File "/Users/r/.virtualenvs/focus-tracker/lib/python3.7/site-packages/google/cloud/language_v1/services/language_service/client.py", line 614, in classify_text
    response = rpc(request, retry=retry, timeout=timeout, metadata=metadata,)
  File "/Users/r/.virtualenvs/focus-tracker/lib/python3.7/site-packages/google/api_core/gapic_v1/method.py", line 145, in __call__
    return wrapped_func(*args, **kwargs)
  File "/Users/r/.virtualenvs/focus-tracker/lib/python3.7/site-packages/google/api_core/retry.py", line 286, in retry_wrapped_func
    on_error=on_error,
  File "/Users/r/.virtualenvs/focus-tracker/lib/python3.7/site-packages/google/api_core/retry.py", line 206, in retry_target
    last_exc,
  File "<string>", line 3, in raise_from
google.api_core.exceptions.RetryError: Deadline of 120.0s exceeded while calling functools.partial(<function _wrap_unary_errors.<locals>.error_remapped_callable at 0x109bcdd40>, document {
  type_: PLAIN_TEXT
  content: "![](current/images/usaco_logo.png)\n\n  * Overview\n  * Training\n  * Contests\n  * History\n  * Staff\n  * Resources\n\n  \n\n##  USACO 2019 US Open Contest, Platinum\n\n##  Problem 1. Tree Boxes\n\nReturn to Problem List  \nContest has ended.\n\n  \n\n![](current/images/medal_none.png)\n\n**Log in to allow submissions in analysis mode**\n\n  \n\nEnglish (en) French (fr) Russian (ru) Spanish (es) Chinese (zh)\n\nFarmer John is planning to build NN (1 N 1051 N 105) farms that will be\nconnected by N 1N 1 roads, forming a tree. Typically, whenever one of his\nfarms is having an issue he is not told the specific farm that is having an\nissue. Instead, he is told that one of the farms along the path from some farm\nAA to another farm BB is having an issue. This is often confusing for Farmer\nJohn, as he usually drives offroad tractors and isn\'t familiar with the road\nsystem.\n\nFarmer John considers the location of a farm to be a 2D point. He would prefer\nto be told that there is a problem in one of the farms in a specifie"
}
, metadata=[('x-goog-api-client', 'gl-python/3.7.4 grpc/1.34.0 gax/1.24.1 gapic/2.0.0')]), last exception: 503 failed to connect to all addresses
E0104 11:52:44.526809000 4645356992 ssl_transport_security.cc:1446]    Handshake failed with fatal error SSL_ERROR_SSL: error:100000f7:SSL routines:OPENSSL_internal:WRONG_VERSION_NUMBER.
Traceback (most recent call last):
  File "/Users/r/.virtualenvs/focus-tracker/lib/python3.7/site-packages/google/api_core/grpc_helpers.py", line 57, in error_remapped_callable
    return callable_(*args, **kwargs)
  File "/Users/r/.virtualenvs/focus-tracker/lib/python3.7/site-packages/grpc/_channel.py", line 923, in __call__
    return _end_unary_response_blocking(state, call, False, None)
  File "/Users/r/.virtualenvs/focus-tracker/lib/python3.7/site-packages/grpc/_channel.py", line 826, in _end_unary_response_blocking
    raise _InactiveRpcError(state)
grpc._channel._InactiveRpcError: <_InactiveRpcError of RPC that terminated with:
	status = StatusCode.UNAVAILABLE
	details = "failed to connect to all addresses"
	debug_error_string = "{"created":"@1609790074.745380000","description":"Failed to pick subchannel","file":"src/core/ext/filters/client_channel/client_channel.cc","file_line":4143,"referenced_errors":[{"created":"@1609790074.745377000","description":"failed to connect to all addresses","file":"src/core/ext/filters/client_channel/lb_policy/pick_first/pick_first.cc","file_line":398,"grpc_status":14}]}"
>

The above exception was the direct cause of the following exception:

Traceback (most recent call last):
  File "/Users/r/.virtualenvs/focus-tracker/lib/python3.7/site-packages/google/api_core/retry.py", line 184, in retry_target
    return target()
  File "/Users/r/.virtualenvs/focus-tracker/lib/python3.7/site-packages/google/api_core/grpc_helpers.py", line 59, in error_remapped_callable
    six.raise_from(exceptions.from_grpc_error(exc), exc)
  File "<string>", line 3, in raise_from
google.api_core.exceptions.ServiceUnavailable: 503 failed to connect to all addresses

The above exception was the direct cause of the following exception:

Traceback (most recent call last):
  File "/Users/r/PycharmProjects/focus-tracker/getdata.py", line 59, in <module>
    managedata.tabulate()
  File "/Users/r/PycharmProjects/focus-tracker/managedata.py", line 33, in tabulate
    listToPut["classification"] = (classificationexample.classify(htstr))
  File "/Users/r/PycharmProjects/focus-tracker/classificationexample.py", line 22, in classify
    response = language_client.classify_text(request={'document': document})
  File "/Users/r/.virtualenvs/focus-tracker/lib/python3.7/site-packages/google/cloud/language_v1/services/language_service/client.py", line 614, in classify_text
    response = rpc(request, retry=retry, timeout=timeout, metadata=metadata,)
  File "/Users/r/.virtualenvs/focus-tracker/lib/python3.7/site-packages/google/api_core/gapic_v1/method.py", line 145, in __call__
    return wrapped_func(*args, **kwargs)
  File "/Users/r/.virtualenvs/focus-tracker/lib/python3.7/site-packages/google/api_core/retry.py", line 286, in retry_wrapped_func
    on_error=on_error,
  File "/Users/r/.virtualenvs/focus-tracker/lib/python3.7/site-packages/google/api_core/retry.py", line 206, in retry_target
    last_exc,
  File "<string>", line 3, in raise_from
google.api_core.exceptions.RetryError: Deadline of 120.0s exceeded while calling functools.partial(<function _wrap_unary_errors.<locals>.error_remapped_callable at 0x10b838d40>, document {
  type_: PLAIN_TEXT
  content: "![](current/images/usaco_logo.png)\n\n  * Overview\n  * Training\n  * Contests\n  * History\n  * Staff\n  * Resources\n\n  \n\n##  USACO 2019 US Open Contest, Platinum\n\n##  Problem 1. Tree Boxes\n\nReturn to Problem List  \nContest has ended.\n\n  \n\n![](current/images/medal_none.png)\n\n**Log in to allow submissions in analysis mode**\n\n  \n\nEnglish (en) French (fr) Russian (ru) Spanish (es) Chinese (zh)\n\nFarmer John is planning to build NN (1 N 1051 N 105) farms that will be\nconnected by N 1N 1 roads, forming a tree. Typically, whenever one of his\nfarms is having an issue he is not told the specific farm that is having an\nissue. Instead, he is told that one of the farms along the path from some farm\nAA to another farm BB is having an issue. This is often confusing for Farmer\nJohn, as he usually drives offroad tractors and isn\'t familiar with the road\nsystem.\n\nFarmer John considers the location of a farm to be a 2D point. He would prefer\nto be told that there is a problem in one of the farms in a specifie"
}
, metadata=[('x-goog-api-client', 'gl-python/3.7.4 grpc/1.34.0 gax/1.24.1 gapic/2.0.0')]), last exception: 503 failed to connect to all addresses
Traceback (most recent call last):
  File "/Users/r/.virtualenvs/focus-tracker/lib/python3.7/site-packages/google/api_core/grpc_helpers.py", line 57, in error_remapped_callable
    return callable_(*args, **kwargs)
  File "/Users/r/.virtualenvs/focus-tracker/lib/python3.7/site-packages/grpc/_channel.py", line 923, in __call__
    return _end_unary_response_blocking(state, call, False, None)
  File "/Users/r/.virtualenvs/focus-tracker/lib/python3.7/site-packages/grpc/_channel.py", line 826, in _end_unary_response_blocking
    raise _InactiveRpcError(state)
grpc._channel._InactiveRpcError: <_InactiveRpcError of RPC that terminated with:
	status = StatusCode.UNAVAILABLE
	details = "failed to connect to all addresses"
	debug_error_string = "{"created":"@1609790197.628333000","description":"Failed to pick subchannel","file":"src/core/ext/filters/client_channel/client_channel.cc","file_line":4143,"referenced_errors":[{"created":"@1609790197.628331000","description":"failed to connect to all addresses","file":"src/core/ext/filters/client_channel/lb_policy/pick_first/pick_first.cc","file_line":398,"grpc_status":14}]}"
>

The above exception was the direct cause of the following exception:

Traceback (most recent call last):
  File "/Users/r/.virtualenvs/focus-tracker/lib/python3.7/site-packages/google/api_core/retry.py", line 184, in retry_target
    return target()
  File "/Users/r/.virtualenvs/focus-tracker/lib/python3.7/site-packages/google/api_core/grpc_helpers.py", line 59, in error_remapped_callable
    six.raise_from(exceptions.from_grpc_error(exc), exc)
  File "<string>", line 3, in raise_from
google.api_core.exceptions.ServiceUnavailable: 503 failed to connect to all addresses

The above exception was the direct cause of the following exception:

Traceback (most recent call last):
  File "/Users/r/PycharmProjects/focus-tracker/getdata.py", line 59, in <module>
    managedata.tabulate()
  File "/Users/r/PycharmProjects/focus-tracker/managedata.py", line 33, in tabulate
    listToPut["classification"] = (classificationexample.classify(htstr))
  File "/Users/r/PycharmProjects/focus-tracker/classificationexample.py", line 22, in classify
    response = language_client.classify_text(request={'document': document})
  File "/Users/r/.virtualenvs/focus-tracker/lib/python3.7/site-packages/google/cloud/language_v1/services/language_service/client.py", line 614, in classify_text
    response = rpc(request, retry=retry, timeout=timeout, metadata=metadata,)
  File "/Users/r/.virtualenvs/focus-tracker/lib/python3.7/site-packages/google/api_core/gapic_v1/method.py", line 145, in __call__
    return wrapped_func(*args, **kwargs)
  File "/Users/r/.virtualenvs/focus-tracker/lib/python3.7/site-packages/google/api_core/retry.py", line 286, in retry_wrapped_func
    on_error=on_error,
  File "/Users/r/.virtualenvs/focus-tracker/lib/python3.7/site-packages/google/api_core/retry.py", line 206, in retry_target
    last_exc,
  File "<string>", line 3, in raise_from
google.api_core.exceptions.RetryError: Deadline of 120.0s exceeded while calling functools.partial(<function _wrap_unary_errors.<locals>.error_remapped_callable at 0x10911ed40>, document {
  type_: PLAIN_TEXT
  content: "![](current/images/usaco_logo.png)\n\n  * Overview\n  * Training\n  * Contests\n  * History\n  * Staff\n  * Resources\n\n  \n\n##  USACO 2019 US Open Contest, Platinum\n\n##  Problem 1. Tree Boxes\n\nReturn to Problem List  \nContest has ended.\n\n  \n\n![](current/images/medal_none.png)\n\n**Log in to allow submissions in analysis mode**\n\n  \n\nEnglish (en) French (fr) Russian (ru) Spanish (es) Chinese (zh)\n\nFarmer John is planning to build NN (1 N 1051 N 105) farms that will be\nconnected by N 1N 1 roads, forming a tree. Typically, whenever one of his\nfarms is having an issue he is not told the specific farm that is having an\nissue. Instead, he is told that one of the farms along the path from some farm\nAA to another farm BB is having an issue. This is often confusing for Farmer\nJohn, as he usually drives offroad tractors and isn\'t familiar with the road\nsystem.\n\nFarmer John considers the location of a farm to be a 2D point. He would prefer\nto be told that there is a problem in one of the farms in a specifie"
}
, metadata=[('x-goog-api-client', 'gl-python/3.7.4 grpc/1.34.0 gax/1.24.1 gapic/2.0.0')]), last exception: 503 failed to connect to all addresses
Traceback (most recent call last):
  File "/Users/r/.virtualenvs/focus-tracker/lib/python3.7/site-packages/google/api_core/grpc_helpers.py", line 57, in error_remapped_callable
    return callable_(*args, **kwargs)
  File "/Users/r/.virtualenvs/focus-tracker/lib/python3.7/site-packages/grpc/_channel.py", line 923, in __call__
    return _end_unary_response_blocking(state, call, False, None)
  File "/Users/r/.virtualenvs/focus-tracker/lib/python3.7/site-packages/grpc/_channel.py", line 826, in _end_unary_response_blocking
    raise _InactiveRpcError(state)
grpc._channel._InactiveRpcError: <_InactiveRpcError of RPC that terminated with:
	status = StatusCode.UNAVAILABLE
	details = "failed to connect to all addresses"
	debug_error_string = "{"created":"@1609790340.568420000","description":"Failed to pick subchannel","file":"src/core/ext/filters/client_channel/client_channel.cc","file_line":4143,"referenced_errors":[{"created":"@1609790340.568418000","description":"failed to connect to all addresses","file":"src/core/ext/filters/client_channel/lb_policy/pick_first/pick_first.cc","file_line":398,"grpc_status":14}]}"
>

The above exception was the direct cause of the following exception:

Traceback (most recent call last):
  File "/Users/r/.virtualenvs/focus-tracker/lib/python3.7/site-packages/google/api_core/retry.py", line 184, in retry_target
    return target()
  File "/Users/r/.virtualenvs/focus-tracker/lib/python3.7/site-packages/google/api_core/grpc_helpers.py", line 59, in error_remapped_callable
    six.raise_from(exceptions.from_grpc_error(exc), exc)
  File "<string>", line 3, in raise_from
google.api_core.exceptions.ServiceUnavailable: 503 failed to connect to all addresses

The above exception was the direct cause of the following exception:

Traceback (most recent call last):
  File "/Users/r/PycharmProjects/focus-tracker/getdata.py", line 59, in <module>
    managedata.tabulate()
  File "/Users/r/PycharmProjects/focus-tracker/managedata.py", line 33, in tabulate
    listToPut["classification"] = (classificationexample.classify(htstr))
  File "/Users/r/PycharmProjects/focus-tracker/classificationexample.py", line 22, in classify
    response = language_client.classify_text(request={'document': document})
  File "/Users/r/.virtualenvs/focus-tracker/lib/python3.7/site-packages/google/cloud/language_v1/services/language_service/client.py", line 614, in classify_text
    response = rpc(request, retry=retry, timeout=timeout, metadata=metadata,)
  File "/Users/r/.virtualenvs/focus-tracker/lib/python3.7/site-packages/google/api_core/gapic_v1/method.py", line 145, in __call__
    return wrapped_func(*args, **kwargs)
  File "/Users/r/.virtualenvs/focus-tracker/lib/python3.7/site-packages/google/api_core/retry.py", line 286, in retry_wrapped_func
    on_error=on_error,
  File "/Users/r/.virtualenvs/focus-tracker/lib/python3.7/site-packages/google/api_core/retry.py", line 206, in retry_target
    last_exc,
  File "<string>", line 3, in raise_from
google.api_core.exceptions.RetryError: Deadline of 120.0s exceeded while calling functools.partial(<function _wrap_unary_errors.<locals>.error_remapped_callable at 0x110d39d40>, document {
  type_: PLAIN_TEXT
  content: "![](current/images/usaco_logo.png)\n\n  * Overview\n  * Training\n  * Contests\n  * History\n  * Staff\n  * Resources\n\n  \n\n##  USACO 2019 US Open Contest, Platinum\n\n##  Problem 1. Tree Boxes\n\nReturn to Problem List  \nContest has ended.\n\n  \n\n![](current/images/medal_none.png)\n\n**Log in to allow submissions in analysis mode**\n\n  \n\nEnglish (en) French (fr) Russian (ru) Spanish (es) Chinese (zh)\n\nFarmer John is planning to build NN (1 N 1051 N 105) farms that will be\nconnected by N 1N 1 roads, forming a tree. Typically, whenever one of his\nfarms is having an issue he is not told the specific farm that is having an\nissue. Instead, he is told that one of the farms along the path from some farm\nAA to another farm BB is having an issue. This is often confusing for Farmer\nJohn, as he usually drives offroad tractors and isn\'t familiar with the road\nsystem.\n\nFarmer John considers the location of a farm to be a 2D point. He would prefer\nto be told that there is a problem in one of the farms in a specifie"
}
, metadata=[('x-goog-api-client', 'gl-python/3.7.4 grpc/1.34.0 gax/1.24.1 gapic/2.0.0')]), last exception: 503 failed to connect to all addresses
Traceback (most recent call last):
  File "/Users/r/.virtualenvs/focus-tracker/lib/python3.7/site-packages/google/api_core/grpc_helpers.py", line 57, in error_remapped_callable
    return callable_(*args, **kwargs)
  File "/Users/r/.virtualenvs/focus-tracker/lib/python3.7/site-packages/grpc/_channel.py", line 923, in __call__
    return _end_unary_response_blocking(state, call, False, None)
  File "/Users/r/.virtualenvs/focus-tracker/lib/python3.7/site-packages/grpc/_channel.py", line 826, in _end_unary_response_blocking
    raise _InactiveRpcError(state)
grpc._channel._InactiveRpcError: <_InactiveRpcError of RPC that terminated with:
	status = StatusCode.UNAVAILABLE
	details = "failed to connect to all addresses"
	debug_error_string = "{"created":"@1609790483.227106000","description":"Failed to pick subchannel","file":"src/core/ext/filters/client_channel/client_channel.cc","file_line":4143,"referenced_errors":[{"created":"@1609790483.227103000","description":"failed to connect to all addresses","file":"src/core/ext/filters/client_channel/lb_policy/pick_first/pick_first.cc","file_line":398,"grpc_status":14}]}"
>

The above exception was the direct cause of the following exception:

Traceback (most recent call last):
  File "/Users/r/.virtualenvs/focus-tracker/lib/python3.7/site-packages/google/api_core/retry.py", line 184, in retry_target
    return target()
  File "/Users/r/.virtualenvs/focus-tracker/lib/python3.7/site-packages/google/api_core/grpc_helpers.py", line 59, in error_remapped_callable
    six.raise_from(exceptions.from_grpc_error(exc), exc)
  File "<string>", line 3, in raise_from
google.api_core.exceptions.ServiceUnavailable: 503 failed to connect to all addresses

The above exception was the direct cause of the following exception:

Traceback (most recent call last):
  File "/Users/r/PycharmProjects/focus-tracker/getdata.py", line 59, in <module>
    managedata.tabulate()
  File "/Users/r/PycharmProjects/focus-tracker/managedata.py", line 33, in tabulate
    listToPut["classification"] = (classificationexample.classify(htstr))
  File "/Users/r/PycharmProjects/focus-tracker/classificationexample.py", line 22, in classify
    response = language_client.classify_text(request={'document': document})
  File "/Users/r/.virtualenvs/focus-tracker/lib/python3.7/site-packages/google/cloud/language_v1/services/language_service/client.py", line 614, in classify_text
    response = rpc(request, retry=retry, timeout=timeout, metadata=metadata,)
  File "/Users/r/.virtualenvs/focus-tracker/lib/python3.7/site-packages/google/api_core/gapic_v1/method.py", line 145, in __call__
    return wrapped_func(*args, **kwargs)
  File "/Users/r/.virtualenvs/focus-tracker/lib/python3.7/site-packages/google/api_core/retry.py", line 286, in retry_wrapped_func
    on_error=on_error,
  File "/Users/r/.virtualenvs/focus-tracker/lib/python3.7/site-packages/google/api_core/retry.py", line 206, in retry_target
    last_exc,
  File "<string>", line 3, in raise_from
google.api_core.exceptions.RetryError: Deadline of 120.0s exceeded while calling functools.partial(<function _wrap_unary_errors.<locals>.error_remapped_callable at 0x10c132d40>, document {
  type_: PLAIN_TEXT
  content: "![](current/images/usaco_logo.png)\n\n  * Overview\n  * Training\n  * Contests\n  * History\n  * Staff\n  * Resources\n\n  \n\n##  USACO 2019 US Open Contest, Platinum\n\n##  Problem 1. Tree Boxes\n\nReturn to Problem List  \nContest has ended.\n\n  \n\n![](current/images/medal_none.png)\n\n**Log in to allow submissions in analysis mode**\n\n  \n\nEnglish (en) French (fr) Russian (ru) Spanish (es) Chinese (zh)\n\nFarmer John is planning to build NN (1 N 1051 N 105) farms that will be\nconnected by N 1N 1 roads, forming a tree. Typically, whenever one of his\nfarms is having an issue he is not told the specific farm that is having an\nissue. Instead, he is told that one of the farms along the path from some farm\nAA to another farm BB is having an issue. This is often confusing for Farmer\nJohn, as he usually drives offroad tractors and isn\'t familiar with the road\nsystem.\n\nFarmer John considers the location of a farm to be a 2D point. He would prefer\nto be told that there is a problem in one of the farms in a specifie"
}
, metadata=[('x-goog-api-client', 'gl-python/3.7.4 grpc/1.34.0 gax/1.24.1 gapic/2.0.0')]), last exception: 503 failed to connect to all addresses
Traceback (most recent call last):
  File "/Users/r/.virtualenvs/focus-tracker/lib/python3.7/site-packages/google/api_core/grpc_helpers.py", line 57, in error_remapped_callable
    return callable_(*args, **kwargs)
  File "/Users/r/.virtualenvs/focus-tracker/lib/python3.7/site-packages/grpc/_channel.py", line 923, in __call__
    return _end_unary_response_blocking(state, call, False, None)
  File "/Users/r/.virtualenvs/focus-tracker/lib/python3.7/site-packages/grpc/_channel.py", line 826, in _end_unary_response_blocking
    raise _InactiveRpcError(state)
grpc._channel._InactiveRpcError: <_InactiveRpcError of RPC that terminated with:
	status = StatusCode.UNAVAILABLE
	details = "failed to connect to all addresses"
	debug_error_string = "{"created":"@1609790626.151562000","description":"Failed to pick subchannel","file":"src/core/ext/filters/client_channel/client_channel.cc","file_line":4143,"referenced_errors":[{"created":"@1609790626.151560000","description":"failed to connect to all addresses","file":"src/core/ext/filters/client_channel/lb_policy/pick_first/pick_first.cc","file_line":398,"grpc_status":14}]}"
>

The above exception was the direct cause of the following exception:

Traceback (most recent call last):
  File "/Users/r/.virtualenvs/focus-tracker/lib/python3.7/site-packages/google/api_core/retry.py", line 184, in retry_target
    return target()
  File "/Users/r/.virtualenvs/focus-tracker/lib/python3.7/site-packages/google/api_core/grpc_helpers.py", line 59, in error_remapped_callable
    six.raise_from(exceptions.from_grpc_error(exc), exc)
  File "<string>", line 3, in raise_from
google.api_core.exceptions.ServiceUnavailable: 503 failed to connect to all addresses

The above exception was the direct cause of the following exception:

Traceback (most recent call last):
  File "/Users/r/PycharmProjects/focus-tracker/getdata.py", line 59, in <module>
    managedata.tabulate()
  File "/Users/r/PycharmProjects/focus-tracker/managedata.py", line 33, in tabulate
    listToPut["classification"] = (classificationexample.classify(htstr))
  File "/Users/r/PycharmProjects/focus-tracker/classificationexample.py", line 22, in classify
    response = language_client.classify_text(request={'document': document})
  File "/Users/r/.virtualenvs/focus-tracker/lib/python3.7/site-packages/google/cloud/language_v1/services/language_service/client.py", line 614, in classify_text
    response = rpc(request, retry=retry, timeout=timeout, metadata=metadata,)
  File "/Users/r/.virtualenvs/focus-tracker/lib/python3.7/site-packages/google/api_core/gapic_v1/method.py", line 145, in __call__
    return wrapped_func(*args, **kwargs)
  File "/Users/r/.virtualenvs/focus-tracker/lib/python3.7/site-packages/google/api_core/retry.py", line 286, in retry_wrapped_func
    on_error=on_error,
  File "/Users/r/.virtualenvs/focus-tracker/lib/python3.7/site-packages/google/api_core/retry.py", line 206, in retry_target
    last_exc,
  File "<string>", line 3, in raise_from
google.api_core.exceptions.RetryError: Deadline of 120.0s exceeded while calling functools.partial(<function _wrap_unary_errors.<locals>.error_remapped_callable at 0x108112d40>, document {
  type_: PLAIN_TEXT
  content: "![](current/images/usaco_logo.png)\n\n  * Overview\n  * Training\n  * Contests\n  * History\n  * Staff\n  * Resources\n\n  \n\n##  USACO 2019 US Open Contest, Platinum\n\n##  Problem 1. Tree Boxes\n\nReturn to Problem List  \nContest has ended.\n\n  \n\n![](current/images/medal_none.png)\n\n**Log in to allow submissions in analysis mode**\n\n  \n\nEnglish (en) French (fr) Russian (ru) Spanish (es) Chinese (zh)\n\nFarmer John is planning to build NN (1 N 1051 N 105) farms that will be\nconnected by N 1N 1 roads, forming a tree. Typically, whenever one of his\nfarms is having an issue he is not told the specific farm that is having an\nissue. Instead, he is told that one of the farms along the path from some farm\nAA to another farm BB is having an issue. This is often confusing for Farmer\nJohn, as he usually drives offroad tractors and isn\'t familiar with the road\nsystem.\n\nFarmer John considers the location of a farm to be a 2D point. He would prefer\nto be told that there is a problem in one of the farms in a specifie"
}
, metadata=[('x-goog-api-client', 'gl-python/3.7.4 grpc/1.34.0 gax/1.24.1 gapic/2.0.0')]), last exception: 503 failed to connect to all addresses
Traceback (most recent call last):
  File "/Users/r/.virtualenvs/focus-tracker/lib/python3.7/site-packages/google/api_core/grpc_helpers.py", line 57, in error_remapped_callable
    return callable_(*args, **kwargs)
  File "/Users/r/.virtualenvs/focus-tracker/lib/python3.7/site-packages/grpc/_channel.py", line 923, in __call__
    return _end_unary_response_blocking(state, call, False, None)
  File "/Users/r/.virtualenvs/focus-tracker/lib/python3.7/site-packages/grpc/_channel.py", line 826, in _end_unary_response_blocking
    raise _InactiveRpcError(state)
grpc._channel._InactiveRpcError: <_InactiveRpcError of RPC that terminated with:
	status = StatusCode.UNAVAILABLE
	details = "failed to connect to all addresses"
	debug_error_string = "{"created":"@1609790768.613331000","description":"Failed to pick subchannel","file":"src/core/ext/filters/client_channel/client_channel.cc","file_line":4143,"referenced_errors":[{"created":"@1609790768.613328000","description":"failed to connect to all addresses","file":"src/core/ext/filters/client_channel/lb_policy/pick_first/pick_first.cc","file_line":398,"grpc_status":14}]}"
>

The above exception was the direct cause of the following exception:

Traceback (most recent call last):
  File "/Users/r/.virtualenvs/focus-tracker/lib/python3.7/site-packages/google/api_core/retry.py", line 184, in retry_target
    return target()
  File "/Users/r/.virtualenvs/focus-tracker/lib/python3.7/site-packages/google/api_core/grpc_helpers.py", line 59, in error_remapped_callable
    six.raise_from(exceptions.from_grpc_error(exc), exc)
  File "<string>", line 3, in raise_from
google.api_core.exceptions.ServiceUnavailable: 503 failed to connect to all addresses

The above exception was the direct cause of the following exception:

Traceback (most recent call last):
  File "/Users/r/PycharmProjects/focus-tracker/getdata.py", line 59, in <module>
    managedata.tabulate()
  File "/Users/r/PycharmProjects/focus-tracker/managedata.py", line 33, in tabulate
    listToPut["classification"] = (classificationexample.classify(htstr))
  File "/Users/r/PycharmProjects/focus-tracker/classificationexample.py", line 22, in classify
    response = language_client.classify_text(request={'document': document})
  File "/Users/r/.virtualenvs/focus-tracker/lib/python3.7/site-packages/google/cloud/language_v1/services/language_service/client.py", line 614, in classify_text
    response = rpc(request, retry=retry, timeout=timeout, metadata=metadata,)
  File "/Users/r/.virtualenvs/focus-tracker/lib/python3.7/site-packages/google/api_core/gapic_v1/method.py", line 145, in __call__
    return wrapped_func(*args, **kwargs)
  File "/Users/r/.virtualenvs/focus-tracker/lib/python3.7/site-packages/google/api_core/retry.py", line 286, in retry_wrapped_func
    on_error=on_error,
  File "/Users/r/.virtualenvs/focus-tracker/lib/python3.7/site-packages/google/api_core/retry.py", line 206, in retry_target
    last_exc,
  File "<string>", line 3, in raise_from
google.api_core.exceptions.RetryError: Deadline of 120.0s exceeded while calling functools.partial(<function _wrap_unary_errors.<locals>.error_remapped_callable at 0x108fa7d40>, document {
  type_: PLAIN_TEXT
  content: "![](current/images/usaco_logo.png)\n\n  * Overview\n  * Training\n  * Contests\n  * History\n  * Staff\n  * Resources\n\n  \n\n##  USACO 2019 US Open Contest, Platinum\n\n##  Problem 1. Tree Boxes\n\nReturn to Problem List  \nContest has ended.\n\n  \n\n![](current/images/medal_none.png)\n\n**Log in to allow submissions in analysis mode**\n\n  \n\nEnglish (en) French (fr) Russian (ru) Spanish (es) Chinese (zh)\n\nFarmer John is planning to build NN (1 N 1051 N 105) farms that will be\nconnected by N 1N 1 roads, forming a tree. Typically, whenever one of his\nfarms is having an issue he is not told the specific farm that is having an\nissue. Instead, he is told that one of the farms along the path from some farm\nAA to another farm BB is having an issue. This is often confusing for Farmer\nJohn, as he usually drives offroad tractors and isn\'t familiar with the road\nsystem.\n\nFarmer John considers the location of a farm to be a 2D point. He would prefer\nto be told that there is a problem in one of the farms in a specifie"
}
, metadata=[('x-goog-api-client', 'gl-python/3.7.4 grpc/1.34.0 gax/1.24.1 gapic/2.0.0')]), last exception: 503 failed to connect to all addresses
Traceback (most recent call last):
  File "/Users/r/.virtualenvs/focus-tracker/lib/python3.7/site-packages/google/api_core/grpc_helpers.py", line 57, in error_remapped_callable
    return callable_(*args, **kwargs)
  File "/Users/r/.virtualenvs/focus-tracker/lib/python3.7/site-packages/grpc/_channel.py", line 923, in __call__
    return _end_unary_response_blocking(state, call, False, None)
  File "/Users/r/.virtualenvs/focus-tracker/lib/python3.7/site-packages/grpc/_channel.py", line 826, in _end_unary_response_blocking
    raise _InactiveRpcError(state)
grpc._channel._InactiveRpcError: <_InactiveRpcError of RPC that terminated with:
	status = StatusCode.UNAVAILABLE
	details = "failed to connect to all addresses"
	debug_error_string = "{"created":"@1609790911.548652000","description":"Failed to pick subchannel","file":"src/core/ext/filters/client_channel/client_channel.cc","file_line":4143,"referenced_errors":[{"created":"@1609790911.548650000","description":"failed to connect to all addresses","file":"src/core/ext/filters/client_channel/lb_policy/pick_first/pick_first.cc","file_line":398,"grpc_status":14}]}"
>

The above exception was the direct cause of the following exception:

Traceback (most recent call last):
  File "/Users/r/.virtualenvs/focus-tracker/lib/python3.7/site-packages/google/api_core/retry.py", line 184, in retry_target
    return target()
  File "/Users/r/.virtualenvs/focus-tracker/lib/python3.7/site-packages/google/api_core/grpc_helpers.py", line 59, in error_remapped_callable
    six.raise_from(exceptions.from_grpc_error(exc), exc)
  File "<string>", line 3, in raise_from
google.api_core.exceptions.ServiceUnavailable: 503 failed to connect to all addresses

The above exception was the direct cause of the following exception:

Traceback (most recent call last):
  File "/Users/r/PycharmProjects/focus-tracker/getdata.py", line 59, in <module>
    managedata.tabulate()
  File "/Users/r/PycharmProjects/focus-tracker/managedata.py", line 33, in tabulate
    listToPut["classification"] = (classificationexample.classify(htstr))
  File "/Users/r/PycharmProjects/focus-tracker/classificationexample.py", line 22, in classify
    response = language_client.classify_text(request={'document': document})
  File "/Users/r/.virtualenvs/focus-tracker/lib/python3.7/site-packages/google/cloud/language_v1/services/language_service/client.py", line 614, in classify_text
    response = rpc(request, retry=retry, timeout=timeout, metadata=metadata,)
  File "/Users/r/.virtualenvs/focus-tracker/lib/python3.7/site-packages/google/api_core/gapic_v1/method.py", line 145, in __call__
    return wrapped_func(*args, **kwargs)
  File "/Users/r/.virtualenvs/focus-tracker/lib/python3.7/site-packages/google/api_core/retry.py", line 286, in retry_wrapped_func
    on_error=on_error,
  File "/Users/r/.virtualenvs/focus-tracker/lib/python3.7/site-packages/google/api_core/retry.py", line 206, in retry_target
    last_exc,
  File "<string>", line 3, in raise_from
google.api_core.exceptions.RetryError: Deadline of 120.0s exceeded while calling functools.partial(<function _wrap_unary_errors.<locals>.error_remapped_callable at 0x10b348d40>, document {
  type_: PLAIN_TEXT
  content: "![](current/images/usaco_logo.png)\n\n  * Overview\n  * Training\n  * Contests\n  * History\n  * Staff\n  * Resources\n\n  \n\n##  USACO 2019 US Open Contest, Platinum\n\n##  Problem 1. Tree Boxes\n\nReturn to Problem List  \nContest has ended.\n\n  \n\n![](current/images/medal_none.png)\n\n**Log in to allow submissions in analysis mode**\n\n  \n\nEnglish (en) French (fr) Russian (ru) Spanish (es) Chinese (zh)\n\nFarmer John is planning to build NN (1 N 1051 N 105) farms that will be\nconnected by N 1N 1 roads, forming a tree. Typically, whenever one of his\nfarms is having an issue he is not told the specific farm that is having an\nissue. Instead, he is told that one of the farms along the path from some farm\nAA to another farm BB is having an issue. This is often confusing for Farmer\nJohn, as he usually drives offroad tractors and isn\'t familiar with the road\nsystem.\n\nFarmer John considers the location of a farm to be a 2D point. He would prefer\nto be told that there is a problem in one of the farms in a specifie"
}
, metadata=[('x-goog-api-client', 'gl-python/3.7.4 grpc/1.34.0 gax/1.24.1 gapic/2.0.0')]), last exception: 503 failed to connect to all addresses
Traceback (most recent call last):
  File "/Users/r/.virtualenvs/focus-tracker/lib/python3.7/site-packages/google/api_core/grpc_helpers.py", line 57, in error_remapped_callable
    return callable_(*args, **kwargs)
  File "/Users/r/.virtualenvs/focus-tracker/lib/python3.7/site-packages/grpc/_channel.py", line 923, in __call__
    return _end_unary_response_blocking(state, call, False, None)
  File "/Users/r/.virtualenvs/focus-tracker/lib/python3.7/site-packages/grpc/_channel.py", line 826, in _end_unary_response_blocking
    raise _InactiveRpcError(state)
grpc._channel._InactiveRpcError: <_InactiveRpcError of RPC that terminated with:
	status = StatusCode.UNAVAILABLE
	details = "failed to connect to all addresses"
	debug_error_string = "{"created":"@1609791053.903692000","description":"Failed to pick subchannel","file":"src/core/ext/filters/client_channel/client_channel.cc","file_line":4143,"referenced_errors":[{"created":"@1609791053.903690000","description":"failed to connect to all addresses","file":"src/core/ext/filters/client_channel/lb_policy/pick_first/pick_first.cc","file_line":398,"grpc_status":14}]}"
>

The above exception was the direct cause of the following exception:

Traceback (most recent call last):
  File "/Users/r/.virtualenvs/focus-tracker/lib/python3.7/site-packages/google/api_core/retry.py", line 184, in retry_target
    return target()
  File "/Users/r/.virtualenvs/focus-tracker/lib/python3.7/site-packages/google/api_core/grpc_helpers.py", line 59, in error_remapped_callable
    six.raise_from(exceptions.from_grpc_error(exc), exc)
  File "<string>", line 3, in raise_from
google.api_core.exceptions.ServiceUnavailable: 503 failed to connect to all addresses

The above exception was the direct cause of the following exception:

Traceback (most recent call last):
  File "/Users/r/PycharmProjects/focus-tracker/getdata.py", line 59, in <module>
    managedata.tabulate()
  File "/Users/r/PycharmProjects/focus-tracker/managedata.py", line 33, in tabulate
    listToPut["classification"] = (classificationexample.classify(htstr))
  File "/Users/r/PycharmProjects/focus-tracker/classificationexample.py", line 22, in classify
    response = language_client.classify_text(request={'document': document})
  File "/Users/r/.virtualenvs/focus-tracker/lib/python3.7/site-packages/google/cloud/language_v1/services/language_service/client.py", line 614, in classify_text
    response = rpc(request, retry=retry, timeout=timeout, metadata=metadata,)
  File "/Users/r/.virtualenvs/focus-tracker/lib/python3.7/site-packages/google/api_core/gapic_v1/method.py", line 145, in __call__
    return wrapped_func(*args, **kwargs)
  File "/Users/r/.virtualenvs/focus-tracker/lib/python3.7/site-packages/google/api_core/retry.py", line 286, in retry_wrapped_func
    on_error=on_error,
  File "/Users/r/.virtualenvs/focus-tracker/lib/python3.7/site-packages/google/api_core/retry.py", line 206, in retry_target
    last_exc,
  File "<string>", line 3, in raise_from
google.api_core.exceptions.RetryError: Deadline of 120.0s exceeded while calling functools.partial(<function _wrap_unary_errors.<locals>.error_remapped_callable at 0x10c2dfd40>, document {
  type_: PLAIN_TEXT
  content: "![](current/images/usaco_logo.png)\n\n  * Overview\n  * Training\n  * Contests\n  * History\n  * Staff\n  * Resources\n\n  \n\n##  USACO 2019 US Open Contest, Platinum\n\n##  Problem 1. Tree Boxes\n\nReturn to Problem List  \nContest has ended.\n\n  \n\n![](current/images/medal_none.png)\n\n**Log in to allow submissions in analysis mode**\n\n  \n\nEnglish (en) French (fr) Russian (ru) Spanish (es) Chinese (zh)\n\nFarmer John is planning to build NN (1 N 1051 N 105) farms that will be\nconnected by N 1N 1 roads, forming a tree. Typically, whenever one of his\nfarms is having an issue he is not told the specific farm that is having an\nissue. Instead, he is told that one of the farms along the path from some farm\nAA to another farm BB is having an issue. This is often confusing for Farmer\nJohn, as he usually drives offroad tractors and isn\'t familiar with the road\nsystem.\n\nFarmer John considers the location of a farm to be a 2D point. He would prefer\nto be told that there is a problem in one of the farms in a specifie"
}
, metadata=[('x-goog-api-client', 'gl-python/3.7.4 grpc/1.34.0 gax/1.24.1 gapic/2.0.0')]), last exception: 503 failed to connect to all addresses
Traceback (most recent call last):
  File "/Users/r/.virtualenvs/focus-tracker/lib/python3.7/site-packages/google/api_core/grpc_helpers.py", line 57, in error_remapped_callable
    return callable_(*args, **kwargs)
  File "/Users/r/.virtualenvs/focus-tracker/lib/python3.7/site-packages/grpc/_channel.py", line 923, in __call__
    return _end_unary_response_blocking(state, call, False, None)
  File "/Users/r/.virtualenvs/focus-tracker/lib/python3.7/site-packages/grpc/_channel.py", line 826, in _end_unary_response_blocking
    raise _InactiveRpcError(state)
grpc._channel._InactiveRpcError: <_InactiveRpcError of RPC that terminated with:
	status = StatusCode.INVALID_ARGUMENT
	details = "The language no is not supported for classify_text analysis."
	debug_error_string = "{"created":"@1609793315.570755000","description":"Error received from peer ipv4:172.217.0.170:443","file":"src/core/lib/surface/call.cc","file_line":1063,"grpc_message":"The language no is not supported for classify_text analysis.","grpc_status":3}"
>

The above exception was the direct cause of the following exception:

Traceback (most recent call last):
  File "/Users/r/PycharmProjects/focus-tracker/getdata.py", line 59, in <module>
    managedata.tabulate()
  File "/Users/r/PycharmProjects/focus-tracker/managedata.py", line 33, in tabulate
    listToPut["classification"] = (classificationexample.classify(htstr))
  File "/Users/r/PycharmProjects/focus-tracker/classificationexample.py", line 22, in classify
    response = language_client.classify_text(request={'document': document})
  File "/Users/r/.virtualenvs/focus-tracker/lib/python3.7/site-packages/google/cloud/language_v1/services/language_service/client.py", line 614, in classify_text
    response = rpc(request, retry=retry, timeout=timeout, metadata=metadata,)
  File "/Users/r/.virtualenvs/focus-tracker/lib/python3.7/site-packages/google/api_core/gapic_v1/method.py", line 145, in __call__
    return wrapped_func(*args, **kwargs)
  File "/Users/r/.virtualenvs/focus-tracker/lib/python3.7/site-packages/google/api_core/retry.py", line 286, in retry_wrapped_func
    on_error=on_error,
  File "/Users/r/.virtualenvs/focus-tracker/lib/python3.7/site-packages/google/api_core/retry.py", line 184, in retry_target
    return target()
  File "/Users/r/.virtualenvs/focus-tracker/lib/python3.7/site-packages/google/api_core/grpc_helpers.py", line 59, in error_remapped_callable
    six.raise_from(exceptions.from_grpc_error(exc), exc)
  File "<string>", line 3, in raise_from
google.api_core.exceptions.InvalidArgument: 400 The language no is not supported for classify_text analysis.
Traceback (most recent call last):
  File "/Users/r/.virtualenvs/focus-tracker/lib/python3.7/site-packages/google/api_core/grpc_helpers.py", line 57, in error_remapped_callable
    return callable_(*args, **kwargs)
  File "/Users/r/.virtualenvs/focus-tracker/lib/python3.7/site-packages/grpc/_channel.py", line 923, in __call__
    return _end_unary_response_blocking(state, call, False, None)
  File "/Users/r/.virtualenvs/focus-tracker/lib/python3.7/site-packages/grpc/_channel.py", line 826, in _end_unary_response_blocking
    raise _InactiveRpcError(state)
grpc._channel._InactiveRpcError: <_InactiveRpcError of RPC that terminated with:
	status = StatusCode.INVALID_ARGUMENT
	details = "The language no is not supported for classify_text analysis."
	debug_error_string = "{"created":"@1609793318.667455000","description":"Error received from peer ipv4:172.217.3.74:443","file":"src/core/lib/surface/call.cc","file_line":1063,"grpc_message":"The language no is not supported for classify_text analysis.","grpc_status":3}"
>

The above exception was the direct cause of the following exception:

Traceback (most recent call last):
  File "/Users/r/PycharmProjects/focus-tracker/getdata.py", line 59, in <module>
    managedata.tabulate()
  File "/Users/r/PycharmProjects/focus-tracker/managedata.py", line 33, in tabulate
    listToPut["classification"] = (classificationexample.classify(htstr))
  File "/Users/r/PycharmProjects/focus-tracker/classificationexample.py", line 22, in classify
    response = language_client.classify_text(request={'document': document})
  File "/Users/r/.virtualenvs/focus-tracker/lib/python3.7/site-packages/google/cloud/language_v1/services/language_service/client.py", line 614, in classify_text
    response = rpc(request, retry=retry, timeout=timeout, metadata=metadata,)
  File "/Users/r/.virtualenvs/focus-tracker/lib/python3.7/site-packages/google/api_core/gapic_v1/method.py", line 145, in __call__
    return wrapped_func(*args, **kwargs)
  File "/Users/r/.virtualenvs/focus-tracker/lib/python3.7/site-packages/google/api_core/retry.py", line 286, in retry_wrapped_func
    on_error=on_error,
  File "/Users/r/.virtualenvs/focus-tracker/lib/python3.7/site-packages/google/api_core/retry.py", line 184, in retry_target
    return target()
  File "/Users/r/.virtualenvs/focus-tracker/lib/python3.7/site-packages/google/api_core/grpc_helpers.py", line 59, in error_remapped_callable
    six.raise_from(exceptions.from_grpc_error(exc), exc)
  File "<string>", line 3, in raise_from
google.api_core.exceptions.InvalidArgument: 400 The language no is not supported for classify_text analysis.
Traceback (most recent call last):
  File "/Users/r/.virtualenvs/focus-tracker/lib/python3.7/site-packages/google/api_core/grpc_helpers.py", line 57, in error_remapped_callable
    return callable_(*args, **kwargs)
  File "/Users/r/.virtualenvs/focus-tracker/lib/python3.7/site-packages/grpc/_channel.py", line 923, in __call__
    return _end_unary_response_blocking(state, call, False, None)
  File "/Users/r/.virtualenvs/focus-tracker/lib/python3.7/site-packages/grpc/_channel.py", line 826, in _end_unary_response_blocking
    raise _InactiveRpcError(state)
grpc._channel._InactiveRpcError: <_InactiveRpcError of RPC that terminated with:
	status = StatusCode.INVALID_ARGUMENT
	details = "The language no is not supported for classify_text analysis."
	debug_error_string = "{"created":"@1609800918.801556000","description":"Error received from peer ipv4:172.217.2.202:443","file":"src/core/lib/surface/call.cc","file_line":1063,"grpc_message":"The language no is not supported for classify_text analysis.","grpc_status":3}"
>

The above exception was the direct cause of the following exception:

Traceback (most recent call last):
  File "/Users/r/PycharmProjects/focus-tracker/getdata.py", line 59, in <module>
    managedata.tabulate()
  File "/Users/r/PycharmProjects/focus-tracker/managedata.py", line 33, in tabulate
    listToPut["classification"] = (classificationexample.classify(htstr))
  File "/Users/r/PycharmProjects/focus-tracker/classificationexample.py", line 22, in classify
    response = language_client.classify_text(request={'document': document})
  File "/Users/r/.virtualenvs/focus-tracker/lib/python3.7/site-packages/google/cloud/language_v1/services/language_service/client.py", line 614, in classify_text
    response = rpc(request, retry=retry, timeout=timeout, metadata=metadata,)
  File "/Users/r/.virtualenvs/focus-tracker/lib/python3.7/site-packages/google/api_core/gapic_v1/method.py", line 145, in __call__
    return wrapped_func(*args, **kwargs)
  File "/Users/r/.virtualenvs/focus-tracker/lib/python3.7/site-packages/google/api_core/retry.py", line 286, in retry_wrapped_func
    on_error=on_error,
  File "/Users/r/.virtualenvs/focus-tracker/lib/python3.7/site-packages/google/api_core/retry.py", line 184, in retry_target
    return target()
  File "/Users/r/.virtualenvs/focus-tracker/lib/python3.7/site-packages/google/api_core/grpc_helpers.py", line 59, in error_remapped_callable
    six.raise_from(exceptions.from_grpc_error(exc), exc)
  File "<string>", line 3, in raise_from
google.api_core.exceptions.InvalidArgument: 400 The language no is not supported for classify_text analysis.
